<?xml version="1.0"?>
<robot name="orihime-t" xmlns:xacro="http://ros.org/wiki/xacro">
    <!--
    <xacro:include filename="$(find realsense2_description)/urdf/_d435.urdf.xacro" />
    -->
    <xacro:include filename="$(find realsense_gazebo_description)/urdf/_d435i.urdf.xacro"/>
    <material name="gray">
        <color rgba="0.5 0.5 0.5 1.0"/>
    </material>
    <material name="red">
        <color rgba="1 0 0 1.0"/>
    </material>

    <!-- xacro defination -->
    <xacro:macro name="wheel_macro" params="parent prefix xyz">
        <joint name="${prefix}_joint" type="continuous">
            <parent link="${parent}"/>
            <child link="${prefix}_link"/>
            <origin xyz="${xyz}" rpy="${radians(-90)} 0 0"/>
            <axis xyz="0 0 1"/>
            <limit velocity="12.0" effort="0.4"/>
            <dynamics damping="0.1"/>
        </joint>
        <transmission name="${prefix}_trans" type="SimpleTransmission">
            <type>transmission_interface/SimpleTransmission</type>
            <joint name="${prefix}_joint">
                <hardwareInterface>hardware_interface/VelocityJointInterface</hardwareInterface>
            </joint>
            <actuator name="${prefix}_motor">
                <mechanicalReduction>1.0</mechanicalReduction>
            </actuator>
        </transmission>
        <link name="${prefix}_link">
            <inertial>
                <origin xyz="0 0 0" rpy="0 0 0"/>
                <mass value="0.1"/>
                <inertia ixx="0.0001" ixy="0.0" ixz="0.0" iyy="0.0001" iyz="0.0" izz="0.0001"/>
            </inertial>
            <visual>
                <geometry>
                    <cylinder length="0.043" radius="0.05"/>
                </geometry>
                <material name="red"/>
            </visual>
            <collision>
                <geometry>
                    <cylinder length="0.043" radius="0.05"/>
                </geometry>
            </collision>
        </link>
        <gazebo reference="${prefix}_link">
            <material>Gazebo/Red</material>
            <mu1 value="2.5"/>
            <mu2 value="2.5"/>
            <kp value="50000"/>
            <kd value="10"/>
        </gazebo>
    </xacro:macro>


    <!--this is the base link for OriHime_t-->
    <link name="base_link"/>

    <joint name="body_joint" type="fixed">
        <parent link="base_link"/>
        <child link="body_link"/>
        <origin xyz="0 0 0.115" rpy="0 0 0"/>
    </joint>

    <link name="body_link">
        <visual>
            <origin xyz="0 0 -0.05" rpy="0 0 1.57"/>
            <geometry>
                <mesh filename="package://orihime_t/meshes/OriHime-T.stl" scale="0.001 0.001 0.001"/>
            </geometry>
            <material name="gray"/>
        </visual>
        <collision>
            <origin xyz="0 0 0" rpy="0 0 0"/>
            <geometry>
                <box size="0.215 0.104 0.13"/>
            </geometry>
        </collision>
        <inertial>
            <origin xyz="-0.061 0 0" rpy="0 0 0"/>
            <mass value="5.45"/>
            <inertia ixx="0.0126" ixy="0.0" ixz="0.0" iyy="0.0287" iyz="0.0" izz="0.0258"/>
        </inertial>
        <visual>
            <origin xyz="-0.071 0 -0.085" rpy="0 0 0"/>
            <geometry>
                <box size="0.02 0.02 0.04"/>
            </geometry>
        </visual>
        <collision>
            <origin xyz="-0.071 0 -0.085" rpy="0 0 0"/>
            <geometry>
                <box size="0.02 0.02 0.04"/>
            </geometry>
        </collision>
        <visual>
            <origin xyz="-0.071 0 -0.105" rpy="0 0 0"/>
            <geometry>
                <sphere radius="0.01"/>
            </geometry>
        </visual>
        <collision>
            <origin xyz="-0.071 0 -0.105" rpy="0 0 0"/>
            <geometry>
                <sphere radius="0.01"/>
            </geometry>
        </collision>
        
        
    </link>

    <gazebo reference="body_link">
        <material>Gazebo/Gray</material>
        <mu1 value="0.5"/>
        <mu2 value="0.5"/>
    </gazebo>
    
    
    <xacro:wheel_macro prefix="left_wheel" parent="body_link" xyz="0.04 0.0735 -0.065"/>
    <xacro:wheel_macro prefix="right_wheel" parent="body_link" xyz="0.04 -0.0735 -0.065"/>
    
    <joint name="d435i_joint" type="fixed">
        <parent link="body_link"/>
        <child link="d435i_link"/>
        <origin xyz="0.08 0 0.475" rpy="0 0 0"/>
    </joint>
    <!--
    <link name="camera_link"/>
    <xacro:sensor_d435 name="camera_d435" topics_ns="camera" parent="camera_link" publish_pointcloud="true">
        <origin xyz="0 0 0" rpy="0 0 0"/>
    </xacro:sensor_d435>
    -->
    <link name="d435i_link"/>
    <xacro:sensor_d435i parent="d435i_link">
        <origin xyz="0 0 0" rpy="0 0 0"/>
    </xacro:sensor_d435i> 
    <gazebo>
        <plugin name="orihime_t_controller" filename="libgazebo_ros_diff_drive.so">
            <commandTopic>cmd_vel</commandTopic>
            <odometryTopic>odom</odometryTopic>
            <odometryFrame>odom</odometryFrame>
            <odometrySource>world</odometrySource>
            <publishOdomTF>true</publishOdomTF>
            <robotBaseFrame>body_link</robotBaseFrame>
            <publishWheelTF>false</publishWheelTF>
            <publishTf>true</publishTf>
            <publishWheelJointState>true</publishWheelJointState>
            <legacyMode>false</legacyMode>
            <updateRate>30</updateRate>
            <leftJoint>left_wheel_joint</leftJoint>
            <rightJoint>right_wheel_joint</rightJoint>
            <wheelSeparation>0.205</wheelSeparation>
            <wheelDiameter>0.1</wheelDiameter>
            <wheelAcceleration>1</wheelAcceleration>
            <wheelTorque>10</wheelTorque>
            <rosDebugLevel>na</rosDebugLevel>
        </plugin>
    </gazebo>
    
    <!--
    <gazebo>
        <plugin name="gazebo_ros_control" filename="libgazebo_ros_control.so">
            <robotNamespace>orihime-t</robotNamespace>
            <robotSimType>gazebo_ros_control/DefaultRobotHWSim</robotSimType>
            <legacyModeNS>true</legacyModeNS>
        </plugin>
    </gazebo>
    -->
</robot>