<?xml version="1.0"?>
<robot name="orihime-t" xmlns:xacro="http://ros.org/wiki/xacro">
    <link name="base_link"/>

    <link name="body_link">
        <visual>
            <origin xyz="0 0 0" rpy="0 0 1.57"/>
            <geometry>
                <mesh filename="package://orihime_t/meshes/OriHime-T.stl" scale="0.001 0.001 0.001"/>
            </geometry>
        </visual>
    </link>

    <link name="left_wheel_link">
    </link>

    <link name="right_wheel_link">
    </link>

    <link name="camera_link">
    </link>

    <joint name="body_joint" type="fixed">
        <parent link="base_link"/>
        <child link="body_link"/>
        <origin xyz="0 0 0.06535" rpy="0 0 0"/>
    </joint>

    <joint name="left_wheel_joint" type="continuous">
        <parent link="body_link"/>
        <child link="left_wheel_link"/>
        <origin xyz="0 0 0" rpy="0 0 0"/>
        <axis xyz="0 0 1"/>
    </joint>

    <joint name="right_wheel_joint" type="continuous">
        <parent link="body_link"/>
        <child link="right_wheel_link"/>
        <origin xyz="0 0 0" rpy="0 0 0"/>
        <axis xyz="0 0 1"/>
    </joint>

    <joint name="camera_joint" type="fixed">
        <parent link="body_link"/>
        <child link="camera_link"/>
        <origin xyz="0 0 0" rpy="0 0 0"/>
    </joint>
</robot>