<?xml version="1.0" encoding="UTF-8"?>
<robot name="orihime-t-real" xmlns:xacro="http://ros.org/wiki/xacro">

    <link name="base_link"/>

    <joint name="body_joint" type="fixed">
        <origin xyz="0 0 0.44" rpy="0 0 0"/>
        <parent link="base_link"/>
        <child link="body_link"/>
    </joint>
    
    <link name="body_link">
      <visual>
        <geometry>
          <box size="0.4 0.352 0.78"/>
        </geometry>
      </visual>
      <collision>
        <geometry>
          <box size="0.4 0.352 0.78"/>
        </geometry>
      </collision>
      <inertial>
        <mass value="8.45"/>
        <origin xyz="0 0 0.45" rpy="0 0 0"/>
        <inertia ixx="0.170" ixy="0.0" ixz="0.0" iyy="0.168" iyz="0.0" izz="0.038"/>
      </inertial>
    </link>

    <joint name="left_wheel_joint" type="continuous">
        <parent link="body_link"/>
        <child link="left_wheel_link"/>
        <origin xyz="0.15 0.1575 -0.39" rpy="-1.57 0 0"/>
        <axis xyz="0 0 1"/>
    </joint>

    <link name="left_wheel_link">
        <visual>
            <origin xyz="0 0 0" rpy="0 0 0"/>
            <geometry>
                <cylinder length="0.045" radius="0.05"/>
            </geometry>
        </visual>
        <collision>
            <origin xyz="0 0 0" rpy="0 0 0"/>
            <geometry>
                <cylinder length="0.045" radius="0.05"/>
            </geometry>
        </collision>
        <inertial>
            <origin xyz="0 0 0"/>
            <mass value="0.3"/>
            <inertia ixx="0.001" ixy="0.0" ixz="0.0"
                     iyy="0.001" iyz="0.0"
                     izz="0.001" />
        </inertial>
    </link>

    <joint name="right_wheel_joint" type="continuous">
        <parent link="body_link"/>
        <child link="right_wheel_link"/>
        <origin xyz="0.15 -0.1575 -0.39" rpy="-1.57 0 0"/>
        <axis xyz="0 0 1"/>
    </joint>

    <link name="right_wheel_link">
        <visual>
            <origin xyz="0 0 0" rpy="0 0 0"/>
            <geometry>
                <cylinder length="0.045" radius="0.05"/>
            </geometry>
        </visual>
        <collision>
            <origin xyz="0 0 0" rpy="0 0 0"/>
            <geometry>
                <cylinder length="0.045" radius="0.05"/>
            </geometry>
        </collision>
        <inertial>
            <origin xyz="0 0 0"/>
            <mass value="0.3"/>
            <inertia ixx="0.001" ixy="0.0" ixz="0.0"
                     iyy="0.001" iyz="0.0"
                     izz="0.001" />
        </inertial>
    </link>

    <joint name="caster_back_left_joint" type="fixed">
        <parent link="body_link"/>
        <child link="caster_back_left_link"/>
        <origin xyz="-0.13 0.16 -0.39" rpy="0 0 0"/>
    </joint>
    
    <link name="caster_back_left_link">
        <visual>
            <origin xyz="0 0 0" rpy="0 0 0"/>
            <geometry>
                <box size="0.03 0.03 0.1"/>
            </geometry>
        </visual>
        <collision>
            <origin xyz="0 0 0" rpy="0 0 0"/>
            <geometry>
                <box size="0.03 0.03 0.1"/>
            </geometry>
        </collision>
        <inertial>
            <origin xyz="0 0 0" />
            <mass value="0.005" />
            <inertia ixx="0.001" ixy="0.0" ixz="0.0"
                     iyy="0.001" iyz="0.0"
                     izz="0.001" />
        </inertial>
    </link>

    <joint name="caster_back_right_joint" type="fixed">
        <parent link="body_link"/>
        <child link="caster_back_right_link"/>
        <origin xyz="-0.13 -0.16 -0.39" rpy="0 0 0"/>
    </joint>
    
    <link name="caster_back_right_link">
        <visual>
            <origin xyz="0 0 0" rpy="0 0 0"/>
            <geometry>
                <box size="0.03 0.03 0.1"/>
            </geometry>
        </visual>
        <collision>
            <origin xyz="0 0 0" rpy="0 0 0"/>
            <geometry>
                <box size="0.03 0.03 0.1"/>
            </geometry>
        </collision>
        <inertial>
            <origin xyz="0 0 0" />
            <mass value="0.005" />
            <inertia ixx="0.001" ixy="0.0" ixz="0.0"
                     iyy="0.001" iyz="0.0"
                     izz="0.001" />
        </inertial>
    </link>

    <joint name="camera_joint" type="fixed">
        <parent link="body_link"/>
        <child link="camera_link"/>
        <origin xyz="0.2 0 -0.24" rpy="0 0 0"/>
    </joint>   
    
    <link name="camera_link"/>
  
  </robot>
  