<?xml version="1.0" ?>
<!-- =================================================================================== -->
<!-- |    This document was autogenerated by xacro from orihime-t.xacro                | -->
<!-- |    EDITING THIS FILE BY HAND IS NOT RECOMMENDED                                 | -->
<!-- =================================================================================== -->
<robot name="orihime-t">
  <material name="gray">
    <color rgba="0.5 0.5 0.5 1.0"/>
  </material>
  <material name="red">
    <color rgba="1 0 0 1.0"/>
  </material>
  <!--this is the base link for OriHime_t-->
  <link name="base_link"/>
  <joint name="body_joint" type="fixed">
    <parent link="base_link"/>
    <child link="body_link"/>
    <origin rpy="0 0 0" xyz="0 0 0.05"/>
  </joint>
  <link name="body_link">
    <visual>
      <origin rpy="0 0 1.57" xyz="0 0 0.017"/>
      <geometry>
        <mesh filename="package://orihime_t/meshes/OriHime-T.stl" scale="0.001 0.001 0.001"/>
      </geometry>
      <material name="gray"/>
    </visual>
    <!-- Base collision, mass and inertia -->
    <collision>
      <origin rpy="0 0 0" xyz="0 0 0.06535"/>
      <geometry>
        <box size="0.215 0.104 0.13"/>
      </geometry>
    </collision>
    <inertial>
      <origin rpy="0 0 0" xyz="0 0 0"/>
      <mass value="1.0"/>
      <inertia ixx="0.0001" ixy="0.0" ixz="0.0" iyy="0.0001" iyz="0.0" izz="0.0001"/>
    </inertial>
  </link>
  <gazebo reference="body_link">
    <material>Gazebo/Gray</material>
  </gazebo>
  <joint name="left_wheel_joint" type="continuous">
    <parent link="body_link"/>
    <child link="left_wheel_link"/>
    <origin rpy="-1.5707963267948966 0 0" xyz="0.04 -0.0735 0"/>
    <axis xyz="0 0 1"/>
  </joint>
  <transmission name="left_wheel_trans" type="SimpleTransmission">
    <type>transmission_interface/SimpleTransmission</type>
    <joint name="left_wheel_joint">
      <hardwareInterface>hardware_interface/VelocityJointInterface</hardwareInterface>
    </joint>
    <actuator name="left_wheel_motor">
      <mechanicalReduction>1.0</mechanicalReduction>
    </actuator>
  </transmission>
  <link name="left_wheel_link">
    <inertial>
      <origin rpy="0 0 0" xyz="0 0 0"/>
      <mass value="0.1"/>
      <inertia ixx="0.0001" ixy="0.0" ixz="0.0" iyy="0.0001" iyz="0.0" izz="0.0001"/>
    </inertial>
    <visual>
      <geometry>
        <cylinder length="0.043" radius="0.05035"/>
      </geometry>
      <material name="red"/>
    </visual>
    <collision>
      <geometry>
        <cylinder length="0.043" radius="0.05035"/>
      </geometry>
    </collision>
  </link>
  <gazebo reference="left_wheel_link">
    <material>Gazebo/Red</material>
    <mu1 value="2.5"/>
    <mu2 value="2.5"/>
    <kp value="50000"/>
    <kd value="10"/>
  </gazebo>
  <joint name="right_wheel_joint" type="continuous">
    <parent link="body_link"/>
    <child link="right_wheel_link"/>
    <origin rpy="-1.5707963267948966 0 0" xyz="0.04 0.0735 0"/>
    <axis xyz="0 0 1"/>
  </joint>
  <transmission name="right_wheel_trans" type="SimpleTransmission">
    <type>transmission_interface/SimpleTransmission</type>
    <joint name="right_wheel_joint">
      <hardwareInterface>hardware_interface/VelocityJointInterface</hardwareInterface>
    </joint>
    <actuator name="right_wheel_motor">
      <mechanicalReduction>1.0</mechanicalReduction>
    </actuator>
  </transmission>
  <link name="right_wheel_link">
    <inertial>
      <origin rpy="0 0 0" xyz="0 0 0"/>
      <mass value="0.1"/>
      <inertia ixx="0.0001" ixy="0.0" ixz="0.0" iyy="0.0001" iyz="0.0" izz="0.0001"/>
    </inertial>
    <visual>
      <geometry>
        <cylinder length="0.043" radius="0.05035"/>
      </geometry>
      <material name="red"/>
    </visual>
    <collision>
      <geometry>
        <cylinder length="0.043" radius="0.05035"/>
      </geometry>
    </collision>
  </link>
  <gazebo reference="right_wheel_link">
    <material>Gazebo/Red</material>
    <mu1 value="2.5"/>
    <mu2 value="2.5"/>
    <kp value="50000"/>
    <kd value="10"/>
  </gazebo>
  <gazebo>
    <plugin filename="libgazebo_ros_control.so" name="gazebo_ros_control">
      <robotNamespace>orihime-t</robotNamespace>
    </plugin>
  </gazebo>
</robot>
