<?xml version="1.0"?>
<robot name="orihime-t" xmlns:xacro="http://ros.org/wiki/xacro">
    <material name="gray">
        <color rgba="0.5 0.5 0.5 1.0"/>
    </material>
    <material name="red">
        <color rgba="1 0 0 1.0"/>
    </material>

    <xacro:macro name="wheel_macro" params="parent prefix xyz">
        <joint name="${prefix}_joint" type="continuous">
            <parent link="${parent}"/>
            <child link="${prefix}_link"/>
            <origin xyz="${xyz}" rpy="${radians(-90)} 0 0"/>
            <axis xyz="0 0 1"/>
        </joint>
        <transmission name="${prefix}_trans" type="SimpleTransmission">
            <type>transmission_interface/SimpleTransmission</type>
            <joint name="${prefix}_joint">
                <hardwareInterface>hardware_interface/VelocityJointInterface</hardwareInterface>
            </joint>
            <actuator name="${prefix}_motor">
                <mechanicalReduction>1.0</mechanicalReduction>
            </actuator>
        </transmission>
        <link name="${prefix}_link">
            <inertial>
                <origin xyz="0 0 0" rpy="0 0 0"/>
                <mass value="0.1"/>
                <inertia ixx="0.0001" ixy="0.0" ixz="0.0" iyy="0.0001" iyz="0.0" izz="0.0001"/>
            </inertial>
            <visual>
                <geometry>
                    <cylinder length="0.043" radius="0.05035"/>
                </geometry>
                <material name="gray"/>
            </visual>
            <collision>
                <geometry>
                    <cylinder length="0.043" radius="0.05035"/>
                </geometry>
            </collision>
        </link>
        <gazebo reference="${prefix}_link">
            <material>Gazebo/Red</material>
            <mu1 value="2.5"/>
            <mu2 value="2.5"/>
            <kp value="50000"/>
            <kd value="10"/>
        </gazebo>
    </xacro:macro>

    <link name="base_link"/>

    <link name="body_link">
        <visual>
            <origin xyz="0 0 0" rpy="0 0 1.57"/>
            <geometry>
                <mesh filename="package://orihime_t/meshes/OriHime-T.stl" scale="0.001 0.001 0.001"/>
            </geometry>
        </visual>
    </link>

    <link name="left_wheel_link">
    </link>

    <link name="right_wheel_link">
    </link>

    <link name="camera_link">
    </link>

    <joint name="body_joint" type="fixed">
        <parent link="base_link"/>
        <child link="body_link"/>
        <origin xyz="0 0 0.06535" rpy="0 0 0"/>
    </joint>

    <joint name="left_wheel_joint" type="continuous">
        <parent link="body_link"/>
        <child link="left_wheel_link"/>
        <origin xyz="0 0 0" rpy="0 0 0"/>
        <axis xyz="0 0 1"/>
    </joint>

    <joint name="right_wheel_joint" type="continuous">
        <parent link="body_link"/>
        <child link="right_wheel_link"/>
        <origin xyz="0 0 0" rpy="0 0 0"/>
        <axis xyz="0 0 1"/>
    </joint>

    <joint name="camera_joint" type="fixed">
        <parent link="body_link"/>
        <child link="camera_link"/>
        <origin xyz="0 0 0" rpy="0 0 0"/>
    </joint>
</robot>